Traceback (most recent call last):
  File "/home/nverhaaren/houghton/ua-lookup.py", line 25, in <module>
    'fromList' : 'False', 'forRefreshStatus' : 'False' })
  File "/home/nverhaaren/.local/lib/python2.7/site-packages/requests/api.py", line 70, in get
    return request('get', url, params=params, **kwargs)
  File "/home/nverhaaren/.local/lib/python2.7/site-packages/requests/api.py", line 56, in request
    return session.request(method=method, url=url, **kwargs)
  File "/home/nverhaaren/.local/lib/python2.7/site-packages/requests/sessions.py", line 488, in request
    resp = self.send(prep, **send_kwargs)
  File "/home/nverhaaren/.local/lib/python2.7/site-packages/requests/sessions.py", line 609, in send
    r = adapter.send(request, **kwargs)
  File "/home/nverhaaren/.local/lib/python2.7/site-packages/requests/adapters.py", line 497, in send
    raise SSLError(e, request=request)
requests.exceptions.SSLError: EOF occurred in violation of protocol (_ssl.c:661)
